Workbook
Name Slicer_Category: #N/A
Name Slicer_Order_Status: #N/A
Name Slicer_Region: #N/A

Sheet Raw Sales Data
A1: Order_ID | B1: clean_date | C1: Clean Name | D1: City | E1: Region | F1: Category | G1: Product | H1: Unit_Price | I1: Quantity | J1: Discount_% | K1: Gross_Total | L1: Discount_Amount | M1: Net_Total | N1: Payment_Method | O1: Order_Status | P1: Sales_Rep
A2: ORD-1000 | B2: 45031 | C2: Dhanushka Silva | D2: Colombo | E2: Western | F2: Books | G2: Cook Book | H2: 1423.47 | I2: 2 | J2: 5 | K2: =I2*H2 -> 2846.94 | L2: =K2*J2/100 -> 142.347 | M2: =K2-L2 -> 2704.593 | N2: Mobile Payment | O2: Completed | P2: Thilini Bandara
A3: ORD-1001 | B3: 45032 | C3: Nimali Perera | D3: Kandy | E3: Central | F3: Clothing | G3: Jeans | H3: 4504.82 | I3: 1 | J3: 5 | K3: =I3*H3 -> 4504.82 | L3: =K3*J3/100 -> 225.241 | M3: =K3-L3 -> 4279.579 | N3: Credit Card | O3: Cancelled | P3: Thilini Bandara
A4: ORD-1002 | B4: 45033 | C4: Ishara Gunasekara | D4: Trincomalee | E4: Eastern | F4: Food & Beverage | G4: Rice 5kg | H4: 2629.4 | I4: 2 | J4: 0 | K4: =I4*H4 -> 5258.8 | L4: =K4*J4/100 -> 0 | M4: =K4-L4 -> 5258.8 | N4: Online Transfer | O4: Completed | P4: Kavya Fernando
A5: ORD-1003 | B5: 45034 | C5: Chamara Rajapaksa | D5: Kandy | E5: Central | F5: Electronics | G5: Headphones | H5: 11032.12 | I5: 3 | J5: 15 | K5: =I5*H5 -> 33096.36 | L5: =K5*J5/100 -> 4964.454 | M5: =K5-L5 -> 28131.906 | N5: Debit Card | O5: Refunded | P5: Amara Perera
A6: ORD-1004 | B6: 45035 | C6: Saman Bandara | D6: Kandy | E6: Central | F6: Home & Garden | G6: Pillow Set | H6: 3536.43 | I6: 5 | J6: 0 | K6: =I6*H6 -> 17682.15 | L6: =K6*J6/100 -> 0 | M6: =K6-L6 -> 17682.15 | N6: Mobile Payment | O6: Completed | P6: Amara Perera
A7: ORD-1005 | B7: 45036 | C7: Thilini Jayasuriya | D7: Jaffna | E7: Northern | F7: Electronics | G7: Laptop | H7: 160994.51 | I7: 4 | J7: 0 | K7: =I7*H7 -> 643978.04 | L7: =K7*J7/100 -> 0 | M7: =K7-L7 -> 643978.04 | N7: Online Transfer | O7: Cancelled | P7: Kavya Fernando
A8: ORD-1006 | B8: 45037 | C8: Anusha Rajapaksa | D8: Negombo | E8: Western | F8: Books | G8: Cook Book | H8: 1560.55 | I8: 1 | J8: 0 | K8: =I8*H8 -> 1560.55 | L8: =K8*J8/100 -> 0 | M8: =K8-L8 -> 1560.55 | N8: Credit Card | O8: Pending | P8: Dinesh Silva
A9: ORD-1007 | B9: 45038 | C9: Saman Dissanayake | D9: Jaffna | E9: Northern | F9: Books | G9: History Book | H9: 1699.06 | I9: 3 | J9: 0 | K9: =I9*H9 -> 5097.18 | L9: =K9*J9/100 -> 0 | M9: =K9-L9 -> 5097.18 | N9: Unknown | O9: Refunded | P9: Amara Perera
A10: ORD-1008 | B10: 45039 | C10: Bandara Wickramasinghe | D10: Kandy | E10: Central | F10: Clothing | G10: Dress | H10: 0 | I10: 3 | J10: 0 | K10: =I10*H10 -> 0 | L10: =K10*J10/100 -> 0 | M10: =K10-L10 -> 0 | N10: Online Transfer | O10: Completed | P10: Ruwan Jayasuriya
A11: ORD-1009 | B11: 45040 | C11: Pradeep Fernando | D11: Negombo | E11: Western | F11: Books | G11: History Book | H11: 1814.03 | I11: 5 | J11: 0 | K11: =I11*H11 -> 9070.15 | L11: =K11*J11/100 -> 0 | M11: =K11-L11 -> 9070.15 | N11: Mobile Payment | O11: Completed | P11: Kavya Fernando
A12: ORD-1011 | B12: 45042 | C12: Kamal Dissanayake | D12: Kurunegala | E12: North Western | F12: Sports | G12: Gym Bag | H12: 4526.2 | I12: 5 | J12: 0 | K12: =I12*H12 -> 22631 | L12: =K12*J12/100 -> 0 | M12: =K12-L12 -> 22631 | N12: Cash | O12: Cancelled | P12: Thilini Bandara
A13: ORD-1012 | B13: 45043 | C13: Dhanushka Rajapaksa | D13: Kandy | E13: Central | F13: Food & Beverage | G13: Spices Pack | H13: 558.98 | I13: 1 | J13: 10 | K13: =I13*H13 -> 558.98 | L13: =K13*J13/100 -> 55.898 | M13: =K13-L13 -> 503.082 | N13: Mobile Payment | O13: Refunded | P13: Dinesh Silva
... A996: ORD-1999 | B996: 46030 | C996: Kavindi Rajapaksa | D996: Kandy | E996: Central | F996: Clothing | G996: Jeans | H996: 4482.38 | I996: 5 | J996: 5 | K996: =I996*H996 -> 22411.9 | L996: =K996*J996/100 -> 1120.595 | M996: =K996-L996 -> 21291.305 | N996: Credit Card | O996: Completed | P996: Kavya Fernando

Sheet Sheet3
A1: Order_ID | B1: clean_date | C1: Month | D1: Clean Name | E1: City | F1: Region | G1: Category | H1: Product | I1: Unit_Price | J1: Quantity | K1: Discount_% | L1: Gross_Total | M1: Discount_Amount | N1: Net_Total | O1: Payment_Method | P1: Order_Status | Q1: Sales_Rep
A2: ORD-1000 | B2: 45031 | C2: =TEXT(B2,"mmm") -> Apr | D2: Dhanushka Silva | E2: Colombo | F2: Western | G2: Books | H2: Cook Book | I2: 1423.47 | J2: 2 | K2: 5 | L2: =J2*I2 -> 2846.94 | M2: =L2*K2/100 -> 142.347 | N2: =L2-M2 -> 2704.593 | O2: Mobile Payment | P2: Completed | Q2: Thilini Bandara
A3: ORD-1001 | B3: 45032 | C3: =TEXT(B3,"mmm") -> Apr | D3: Nimali Perera | E3: Kandy | F3: Central | G3: Clothing | H3: Jeans | I3: 4504.82 | J3: 1 | K3: 5 | L3: =J3*I3 -> 4504.82 | M3: =L3*K3/100 -> 225.241 | N3: =L3-M3 -> 4279.579 | O3: Credit Card | P3: Cancelled | Q3: Thilini Bandara
A4: ORD-1002 | B4: 45033 | C4: =TEXT(B4,"mmm") -> Apr | D4: Ishara Gunasekara | E4: Trincomalee | F4: Eastern | G4: Food & Beverage | H4: Rice 5kg | I4: 2629.4 | J4: 2 | K4: 0 | L4: =J4*I4 -> 5258.8 | M4: =L4*K4/100 -> 0 | N4: =L4-M4 -> 5258.8 | O4: Online Transfer | P4: Completed | Q4: Kavya Fernando
A5: ORD-1003 | B5: 45034 | C5: =TEXT(B5,"mmm") -> Apr | D5: Chamara Rajapaksa | E5: Kandy | F5: Central | G5: Electronics | H5: Headphones | I5: 11032.12 | J5: 3 | K5: 15 | L5: =J5*I5 -> 33096.36 | M5: =L5*K5/100 -> 4964.454 | N5: =L5-M5 -> 28131.906 | O5: Debit Card | P5: Refunded | Q5: Amara Perera
A6: ORD-1004 | B6: 45035 | C6: =TEXT(B6,"mmm") -> Apr | D6: Saman Bandara | E6: Kandy | F6: Central | G6: Home & Garden | H6: Pillow Set | I6: 3536.43 | J6: 5 | K6: 0 | L6: =J6*I6 -> 17682.15 | M6: =L6*K6/100 -> 0 | N6: =L6-M6 -> 17682.15 | O6: Mobile Payment | P6: Completed | Q6: Amara Perera
A7: ORD-1005 | B7: 45036 | C7: =TEXT(B7,"mmm") -> Apr | D7: Thilini Jayasuriya | E7: Jaffna | F7: Northern | G7: Electronics | H7: Laptop | I7: 160994.51 | J7: 4 | K7: 0 | L7: =J7*I7 -> 643978.04 | M7: =L7*K7/100 -> 0 | N7: =L7-M7 -> 643978.04 | O7: Online Transfer | P7: Cancelled | Q7: Kavya Fernando
A8: ORD-1006 | B8: 45037 | C8: =TEXT(B8,"mmm") -> Apr | D8: Anusha Rajapaksa | E8: Negombo | F8: Western | G8: Books | H8: Cook Book | I8: 1560.55 | J8: 1 | K8: 0 | L8: =J8*I8 -> 1560.55 | M8: =L8*K8/100 -> 0 | N8: =L8-M8 -> 1560.55 | O8: Credit Card | P8: Pending | Q8: Dinesh Silva
A9: ORD-1007 | B9: 45038 | C9: =TEXT(B9,"mmm") -> Apr | D9: Saman Dissanayake | E9: Jaffna | F9: Northern | G9: Books | H9: History Book | I9: 1699.06 | J9: 3 | K9: 0 | L9: =J9*I9 -> 5097.18 | M9: =L9*K9/100 -> 0 | N9: =L9-M9 -> 5097.18 | O9: Unknown | P9: Refunded | Q9: Amara Perera
A10: ORD-1009 | B10: 45040 | C10: =TEXT(B10,"mmm") -> Apr | D10: Pradeep Fernando | E10: Negombo | F10: Western | G10: Books | H10: History Book | I10: 1814.03 | J10: 5 | K10: 0 | L10: =J10*I10 -> 9070.15 | M10: =L10*K10/100 -> 0 | N10: =L10-M10 -> 9070.15 | O10: Mobile Payment | P10: Completed | Q10: Kavya Fernando
A11: ORD-1011 | B11: 45042 | C11: =TEXT(B11,"mmm") -> Apr | D11: Kamal Dissanayake | E11: Kurunegala | F11: North Western | G11: Sports | H11: Gym Bag | I11: 4526.2 | J11: 5 | K11: 0 | L11: =J11*I11 -> 22631 | M11: =L11*K11/100 -> 0 | N11: =L11-M11 -> 22631 | O11: Cash | P11: Cancelled | Q11: Thilini Bandara
A12: ORD-1012 | B12: 45043 | C12: =TEXT(B12,"mmm") -> Apr | D12: Dhanushka Rajapaksa | E12: Kandy | F12: Central | G12: Food & Beverage | H12: Spices Pack | I12: 558.98 | J12: 1 | K12: 10 | L12: =J12*I12 -> 558.98 | M12: =L12*K12/100 -> 55.898 | N12: =L12-M12 -> 503.082 | O12: Mobile Payment | P12: Refunded | Q12: Dinesh Silva
A13: ORD-1013 | B13: 45044 | C13: =TEXT(B13,"mmm") -> Apr | D13: Dilini Pathirana | E13: Jaffna | F13: Northern | G13: Health & Beauty | H13: Toothpaste | I13: 357.63 | J13: 2 | K13: 0 | L13: =J13*I13 -> 715.26 | M13: =L13*K13/100 -> 0 | N13: =L13-M13 -> 715.26 | O13: Credit Card | P13: Pending | Q13: Thilini Bandara
... A991: ORD-1999 | B991: 46030 | C991: =TEXT(B991,"mmm") -> Jan | D991: Kavindi Rajapaksa | E991: Kandy | F991: Central | G991: Clothing | H991: Jeans | I991: 4482.38 | J991: 5 | K991: 5 | L991: =J991*I991 -> 22411.9 | M991: =L991*K991/100 -> 1120.595 | N991: =L991-M991 -> 21291.305 | O991: Credit Card | P991: Completed | Q991: Kavya Fernando

Sheet KPI
A1: Total Revenue | B1: =SUM(Sheet3!N:N) -> 41693325
A2: Total Orders | B2: =COUNTA(Sheet3!A:A)-1 -> 990
A3: Total Quantity Sold | B3: =SUM(Sheet3!J:J) -> 3004
A4: Completed Orders | B4: =COUNTIF(Sheet3!P:P,"Completed") -> 557
A5: Cancelled Orders | B5: =COUNTIF(Sheet3!P:P,"Cancelled") -> 166
A6: Pending Orders | B6: =COUNTIF(Sheet3!P:P,"Pending") -> 140
A7: Completion Rate | B7: =B4/B2 -> 0.56262626

Sheet Detail1
A1: Details for Sum of Net_Total - Month: Jan
A3: Order_ID | B3: clean_date | C3: Month | D3: Clean Name | E3: City | F3: Region | G3: Category | H3: Product | I3: Unit_Price | J3: Quantity | K3: Discount_% | L3: Gross_Total | M3: Discount_Amount | N3: Net_Total | O3: Payment_Method | P3: Order_Status | Q3: Sales_Rep
A4: ORD-1999 | B4: 46030 | C4: Jan | D4: Kavindi Rajapaksa | E4: Kandy | F4: Central | G4: Clothing | H4: Jeans | I4: 4482.38 | J4: 5 | K4: 5 | L4: 22411.9 | M4: 1120.595 | N4: 21291.305 | O4: Credit Card | P4: Completed | Q4: Kavya Fernando
A5: ORD-1998 | B5: 46029 | C5: Jan | D5: Nimali Fernando | E5: Negombo | F5: Western | G5: Health & Beauty | H5: Face Cream | I5: 1430.3 | J5: 5 | K5: 10 | L5: 7151.5 | M5: 715.15 | N5: 6436.35 | O5: Cash | P5: Refunded | Q5: Amara Perera
A6: ORD-1997 | B6: 46028 | C6: Jan | D6: Kavindi Bandara | E6: Galle | F6: Southern | G6: Books | H6: Novel | I6: 816.53 | J6: 4 | K6: 15 | L6: 3266.12 | M6: 489.918 | N6: 2776.202 | O6: Cash | P6: Completed | Q6: Amara Perera
A7: ORD-1996 | B7: 46027 | C7: Jan | D7: Sanduni Dissanayake | E7: Trincomalee | F7: Eastern | G7: Clothing | H7: T-Shirt | I7: 1393.06 | J7: 4 | K7: 0 | L7: 5572.24 | M7: 0 | N7: 5572.24 | O7: Online Transfer | P7: Cancelled | Q7: Ruwan Jayasuriya
A8: ORD-1995 | B8: 46026 | C8: Jan | D8: Roshani Fernando | E8: Badulla | F8: Uva | G8: Clothing | H8: Jeans | I8: 4219.97 | J8: 4 | K8: 0 | L8: 16879.88 | M8: 0 | N8: 16879.88 | O8: Debit Card | P8: Completed | Q8: Kavya Fernando
A9: ORD-1994 | B9: 46025 | C9: Jan | D9: Thilak Wickramasinghe | E9: Negombo | F9: Western | G9: Sports | H9: Gym Bag | I9: 4190.08 | J9: 2 | K9: 0 | L9: 8380.16 | M9: 0 | N9: 8380.16 | O9: Debit Card | P9: Completed | Q9: Ruwan Jayasuriya
A10: ORD-1993 | B10: 46024 | C10: Jan | D10: Rajith Silva | E10: Kurunegala | F10: North Western | G10: Books | H10: Cook Book | I10: 1611.01 | J10: 5 | K10: 0 | L10: 8055.05 | M10: 0 | N10: 8055.05 | O10: Credit Card | P10: Refunded | Q10: Ruwan Jayasuriya
A11: ORD-1992 | B11: 46023 | C11: Jan | D11: Nimali Pathirana | E11: Colombo | F11: Western | G11: Health & Beauty | H11: Vitamins | I11: 2076.48 | J11: 3 | K11: 15 | L11: 6229.44 | M11: 934.416 | N11: 5295.024 | O11: Debit Card | P11: Completed | Q11: Thilini Bandara
A12: ORD-1657 | B12: 45688 | C12: Jan | D12: Anusha Gunasekara | E12: Trincomalee | F12: Eastern | G12: Electronics | H12: Tablet | I12: 63263.63 | J12: 5 | K12: 0 | L12: 316318.15 | M12: 0 | N12: 316318.15 | O12: Cash | P12: Pending | Q12: Dinesh Silva
A13: ORD-1656 | B13: 45687 | C13: Jan | D13: Rajith Jayasuriya | E13: Kandy | F13: Central | G13: Sports | H13: Yoga Mat | I13: 2617.88 | J13: 1 | K13: 5 | L13: 2617.88 | M13: 130.894 | N13: 2486.986 | O13: Debit Card | P13: Completed | Q13: Amara Perera
A14: ORD-1655 | B14: 45686 | C14: Jan | D14: Dhanushka Perera | E14: Kandy | F14: Central | G14: Home & Garden | H14: Garden Hose | I14: 2817.32 | J14: 3 | K14: 10 | L14: 8451.96 | M14: 845.196 | N14: 7606.764 | O14: Debit Card | P14: Cancelled | Q14: Thilini Bandara
A15: ORD-1654 | B15: 45685 | C15: Jan | D15: Rajith Perera | E15: Badulla | F15: Uva | G15: Home & Garden | H15: Curtains | I15: 5911.62 | J15: 4 | K15: 15 | L15: 23646.48 | M15: 3546.972 | N15: 20099.508 | O15: Debit Card | P15: Cancelled | Q15: Ruwan Jayasuriya
... A73: ORD-1261 | B73: 45292 | C73: Jan | D73: Rajith Bandara | E73: Galle | F73: Southern | G73: Books | H73: History Book | I73: 1629.69 | J73: 4 | K73: 15 | L73: 6518.76 | M73: 977.814 | N73: 5540.946 | O73: Credit Card | P73: Completed | Q73: Kavya Fernando

Sheet Detail2
A1: Details for Sum of Net_Total - City: Colombo
A3: Order_ID | B3: clean_date | C3: Month | D3: Clean Name | E3: City | F3: Region | G3: Category | H3: Product | I3: Unit_Price | J3: Quantity | K3: Discount_% | L3: Gross_Total | M3: Discount_Amount | N3: Net_Total | O3: Payment_Method | P3: Order_Status | Q3: Sales_Rep
A4: ORD-1000 | B4: 45031 | C4: Apr | D4: Dhanushka Silva | E4: Colombo | F4: Western | G4: Books | H4: Cook Book | I4: 1423.47 | J4: 2 | K4: 5 | L4: 2846.94 | M4: 142.347 | N4: 2704.593 | O4: Mobile Payment | P4: Completed | Q4: Thilini Bandara
A5: ORD-1992 | B5: 46023 | C5: Jan | D5: Nimali Pathirana | E5: Colombo | F5: Western | G5: Health & Beauty | H5: Vitamins | I5: 2076.48 | J5: 3 | K5: 15 | L5: 6229.44 | M5: 934.416 | N5: 5295.024 | O5: Debit Card | P5: Completed | Q5: Thilini Bandara
A6: ORD-1990 | B6: 46021 | C6: Dec | D6: Ruwan Wickramasinghe | E6: Colombo | F6: Western | G6: Books | H6: Textbook | I6: 2744.77 | J6: 2 | K6: 15 | L6: 5489.54 | M6: 823.431 | N6: 4666.109 | O6: Cash | P6: Completed | Q6: Kavya Fernando
A7: ORD-1979 | B7: 46010 | C7: Dec | D7: Sanduni Perera | E7: Colombo | F7: Western | G7: Electronics | H7: Camera | I7: 99650.34 | J7: 2 | K7: 0 | L7: 199300.68 | M7: 0 | N7: 199300.68 | O7: Online Transfer | P7: Completed | Q7: Thilini Bandara
A8: ORD-1969 | B8: 46000 | C8: Dec | D8: Kavindi Dissanayake | E8: Colombo | F8: Western | G8: Food & Beverage | H8: Tea 500g | I8: 737.71 | J8: 3 | K8: 15 | L8: 2213.13 | M8: 331.9695 | N8: 1881.1605 | O8: Credit Card | P8: Completed | Q8: Ruwan Jayasuriya
A9: ORD-1961 | B9: 45992 | C9: Dec | D9: Chamara Kumara | E9: Colombo | F9: Western | G9: Books | H9: Self Help | I9: 1248.62 | J9: 3 | K9: 0 | L9: 3745.86 | M9: 0 | N9: 3745.86 | O9: Mobile Payment | P9: Cancelled | Q9: Thilini Bandara
A10: ORD-1945 | B10: 45976 | C10: Nov | D10: Hasini Wickramasinghe | E10: Colombo | F10: Western | G10: Electronics | H10: Smartphone | I10: 85104.52 | J10: 3 | K10: 0 | L10: 255313.56 | M10: 0 | N10: 255313.56 | O10: Credit Card | P10: Completed | Q10: Amara Perera
A11: ORD-1935 | B11: 45966 | C11: Nov | D11: Thilak Senanayake | E11: Colombo | F11: Western | G11: Health & Beauty | H11: Vitamins | I11: 2181.31 | J11: 2 | K11: 0 | L11: 4362.62 | M11: 0 | N11: 4362.62 | O11: Credit Card | P11: Completed | Q11: Ruwan Jayasuriya
A12: ORD-1931 | B12: 45962 | C12: Nov | D12: Ruwan Kumara | E12: Colombo | F12: Western | G12: Sports | H12: Yoga Mat | I12: 2404.45 | J12: 1 | K12: 5 | L12: 2404.45 | M12: 120.2225 | N12: 2284.2275 | O12: Mobile Payment | P12: Completed | Q12: Dinesh Silva
A13: ORD-1920 | B13: 45951 | C13: Oct | D13: Dhanushka Rajapaksa | E13: Colombo | F13: Western | G13: Books | H13: Cook Book | I13: 1612.03 | J13: 3 | K13: 5 | L13: 4836.09 | M13: 241.8045 | N13: 4594.2855 | O13: Online Transfer | P13: Completed | Q13: Thilini Bandara
A14: ORD-1916 | B14: 45947 | C14: Oct | D14: Chamara Bandara | E14: Colombo | F14: Western | G14: Home & Garden | H14: Lamp | I14: 4518.07 | J14: 3 | K14: 10 | L14: 13554.21 | M14: 1355.421 | N14: 12198.789 | O14: Online Transfer | P14: Refunded | Q14: Kavya Fernando
A15: ORD-1911 | B15: 45942 | C15: Oct | D15: Sanduni Gunasekara | E15: Colombo | F15: Western | G15: Electronics | H15: Smartphone | I15: 89653.64 | J15: 4 | K15: 15 | L15: 358614.56 | M15: 53792.184 | N15: 304822.38 | O15: Online Transfer | P15: Cancelled | Q15: Kavya Fernando
... A93: ORD-1099 | B93: 45130 | C93: Jul | D93: Malika Perera | E93: Colombo | F93: Western | G93: Food & Beverage | H93: Rice 5kg | I93: 2396.68 | J93: 3 | K93: 5 | L93: 7190.04 | M93: 359.502 | N93: 6830.538 | O93: Credit Card | P93: Completed | Q93: Thilini Bandara

Sheet Pivot Tables
A1: Row Labels | B1: Sum of Net_Total
A2: Jan | B2: 1834998.4
A3: Feb | B3: 2945804.8
A4: Mar | B4: 2492592.7
A5: Apr | B5: 3549473.6
A6: May | B6: 3768683.3
A7: Jun | B7: 3839063.1
A8: Jul | B8: 5384950.6
A9: Aug | B9: 3120479.3
A10: Sep | B10: 3305933.2
A11: Oct | B11: 4317518.1
A12: Nov | B12: 3234209.6
A13: Dec | B13: 3899618.2
A14: Grand Total | B14: 41693325
A19: Row Labels | B19: Sum of Net_Total
A20: Ratnapura | B20: 7527339.4
A21: Kandy | B21: 6059056.1
A22: Colombo | B22: 4353763.7
A23: Negombo | B23: 4282421.4
A24: Badulla | B24: 4063421.4
A25: Matara | B25: 3772583.2
A26: Jaffna | B26: 3312728.1
A27: Trincomalee | B27: 2996145.3
A28: Kurunegala | B28: 2975030.5
A29: Galle | B29: 2350835.9
A30: Grand Total | B30: 41693325
A36: Row Labels | B36: Sum of Net_Total
A37: Laptop | B37: 10139255
A38: Camera | B38: 6992425.8
A39: Smart TV | B39: 6915558.6
A40: Smartphone | B40: 5861135.5
A41: Tablet | B41: 3324724.7
A42: Cookware Set | B42: 932626.51
A43: Headphones | B43: 880770.39
A44: Saree | B44: 735262.65
A45: Running Shoes | B45: 673416.96
A46: Cricket Bat | B46: 445621.53
A47: Grand Total | B47: 36900797
A80: Row Labels | B80: Sum of Net_Total
A81: Debit Card | B81: 0.26775028
...

Sheet Sheet6
